Workbook

Sheet CE-Only POV
A1: HATCH Demo Build POV — CE-Only Release 1
A3: Decision | B3: Keep F&O out of the demo. Position Release 1 as D365 Sales/Dataverse + Power Platform + Customer Insights - Journeys or external marketing + TMS ISV + QuickBooks + Power BI.
A4: Blueprint gate | B4: During blueprint, decide whether F&O has a compelling Release 1 business case. If not, proceed with CE-only architecture and keep future ERP integration as a later option.
A5: Demo implication | B5: Remove active Dual-Write and F&O build assumptions from demo steps; use TMS/ISV integration for freight/shipment events and QuickBooks handoff for Phase 1 finance.
A6: Why | B6: The RFI and demo script emphasize CRM/OMS ownership of customer, opportunity, quote, customer PO, commercial order, TMS integration, invoice-ready workflow, and reporting.

Sheet Demo Build Tracker
A1: HATCH CRM & OMS Demo Build Tracker
A2: Structured tracker for demo build-out, based on the uploaded 120-minute CRM & Order Orchestration vendor demo script.
A4: Scenario | B4: Scenario timing | C4: Expected evidence | D4: Step ID | E4: Demo step / use case | F4: Hero record / link | G4: Primary system / role | H4: Demo build (CE-only PoV: CE / Power Platform / CI-J / TMS) | I4: Questions for Molly | J4: Build status | K4: Remaining Build items | L4: Priority | M4: Owner | N4: Source line | O4: Notes
A5: Introduction and architecture | B5: 0:00–0:05 | C5: Proposed modules, user roles, implementation partner, and system role. | D5: 0.1 | E5: Orient evaluators to proposed modules, user roles, implementation partner, and system role before entering the scenario flow. | F5: Architecture overview / role map | G5: Solution architect / vendor lead | H5: Architecture/demo shell: position demo as Release 1 CE-first. Show D365 Sales/Dataverse as the customer and commercial-order hub, Power Platform for workflow/pricing/orchestration, CI-J or external marketing attribution, Power BI reporting, TMS ISV integration, and QuickBooks handoff. F&O is not in demo; evaluate in blueprint only if there is a compelling Release 1 business reason. | I5: * Talk about MSFT Elevate pricing, etc. | J5: Not started | L5: High | M5: Serena (on behalf of MSFT, Elevate) | N5: Agenda | O5: Keep corporate overview brief; use this row to capture architecture gaps and named third-party components.
A6: Scenario 1 — account, territory, and opportunity | B6: 0:05–0:20 | C6: Customer 360, relationship history, funding, health, territory, tasks, and demand opportunity. | D6: 1.1 | E6: Open the Central Pennsylvania Food Bank account and show contacts, territory ownership, relationship history, product preferences, funding notes, delivery locations, open orders, and account health. | F6: https://generaldemosl.crm.dynamics.com/main.aspx?appid=cdda307e-2b91-f111-b8da-000d3a340666&forceUCI=1&pagetype=entityrecord&etn=account&id=669ddb12-ba91-f111-b8dc-000d3a340c29 | G6: CRM / seller | H6: CE/Dataverse: configure Account table for food bank profile; related Contacts; Customeraddress (OOB Address child table + location types for HATCH); product preferences fields; funding notes; account health fields; activity timeline. Power BI: optional account health tile. Sales insights for relationship health (And connectivity back tO leads/opps) | I6: * Definition of account health (A: account rel - recent orders, age of account, # of opps) * territory ownership - is that in context of sales? E.g. territory leader (account owner's territory, 1:N territory:sellers for now) * relationship history - is this just activity management? * product preferences - is that free form or related to a particular product (e.g. eggs) -A: 80% eggs, 20% others. Visibility into prev. orders * funding notes - free form, funding cycles/timing (qtr, etc) * delivery loc: different delivery locations • contacts :e .g. purchasing manager (show the title/role in the grid), talk track: ability to track different roles/FTE-contractor relationship | J6: In build | K6: Update other accounts to be food banks and vendors (farms) Add contacts, addresses, activities/notes, etc. to Central Penn Food bank Clean form for demo (make it simple as possible) | L6: Must have | N6: L8
A7: Scenario 1 — account, territory, and opportunity | B7: 0:05–0:20 | C7: Customer 360, relationship history, funding, health, territory, tasks, and demand opportunity. | D7: 1.2 | E7: Create a new demand opportunity for 18 pallets of large cage-free eggs requested for the following week. | F7: https://generaldemosl.crm.dynamics.com/main.aspx?appid=cdda307e-2b91-f111-b8da-000d3a340666&forceUCI=1&pagetype=entityrecord&etn=opportunity&id=395ca505-faf0-4044-a93f-3e24d92d625e | G7: CRM / seller | H7: CE/D365 Sales: configure Opportunity form/view for HATCH demand capture; add product, requested pallets, dozen quantity, requested delivery week/window, food bank capacity, and funding context fields. Configure product master, units (pallets), use opportunity products so that they flow to quotes | I7: can we assume an opp can be for multiple products (OOB behavior) A: Not for now - assume eggs or other proteins (due to drop ship model) NOTE: they do warehouse non eggs , opps are called "pre-orders" in current world. RENAME Opps as Pre-Orders * Egg Opps typically just for one type but perhaps for the future it can be different types (E.g. organic, cage free etc.) * today just chicken eggs | J7: In build | K7: HATCH Opp form custom fields/relationships, etc. Tasks, notes, activities, emails | L7: Must have | N7: L9
A8: Scenario 1 — account, territory, and opportunity | B8: 0:05–0:20 | C8: Customer 360, relationship history, funding, health, territory, tasks, and demand opportunity. | D8: 1.3 | E8: Capture funding source, probability, expected order date, requested delivery window, next action, product and volume, and food bank capacity. | F8: Opportunity detail record | G8: CRM / seller | H8: CE/Dataverse + Power Platform: configure Funding Program/Profile table or fields (Choice field, simpler); PASS eligibility, fiscal/funding expiration, probability, expected order date, next action, product/volume, and capacity fields/validation. | I8: what is expected order date, expected delivery date? Next actions in terms of fulfilment or in terms of opp pursuit assuming product, volume are opportunity products what is foodbank capacity, is that just an attribute of account? * funding source: free form * expected order date: ship date * requested delivery date * food bank capacity - e.g. can only accept 2 pallets at a time (free text ) * next action: re: opp (e.g. demand identified, ..., order created,...) | J8: Not started | L8: Must have | N8: L10
A9: Scenario 1 — account, territory, and opportunity | B9: 0:05–0:20 | C9: Customer 360, relationship history, funding, health, territory, tasks, and demand opportunity. | D9: 1.4 | E9: Assign the opportunity to the Mid-Atlantic territory and demonstrate reassignment or coverage backup without losing history. | F9: Territory: Mid-Atlantic / owner assignment | G9: CRM / sales manager | H9: CE/D365 Sales: configure Territory hierarchy, account/opportunity owner assignment, reassignment demo path, audit/history capture; optional custom effective-dating table if needed. | I9: is the intent just to show that we can reassign to others in a territory and they can view all the opp info? * assign to person show their territory | J9: Not started | L9: Should have | N9: L11
A10: Scenario 1 — account, territory, and opportunity | B10: 0:05–0:20 | C10: Customer 360, relationship history, funding, health, territory, tasks, and demand opportunity. | D10: 1.5 | E10: Show how email, meeting notes, tasks, and next steps are captured with minimal seller effort. | F10: Activity timeline / next best action | G10: CRM / seller | H10: CE + Microsoft 365 integration (Copilot in Sales/sales copilot): configure activity timeline, tasks, notes, email/meeting capture, seller next-step view; optionally use Copilot/Power Automate to reduce seller effort. | I10: do we want to leverage some AI here (e.g. summarization of raw meeting notes into activity or note) * stick with standard AI functionalities for now - show AI stuff in the context of simple workflow (in this case ease of capturing notes, tasks, etc.) - rest fancy agents first party and custom just mention as talk tracks - dont over AI the demo | J10: Not started | L10: Should have | N10: L12
A11: Scenario 1 — account, territory, and opportunity | B11: 0:05–0:20 | C11: Customer 360, relationship history, funding, health, territory, tasks, and demand opportunity. | D11: 1.6 | E11: Show pipeline and forecast impact at rep, territory, and organization level. | F11: Pipeline dashboard / forecast view | G11: CRM + analytics / manager | H11: Power BI + CE views: build pipeline/forecast report by rep, territory, and org; connect to Dataverse opportunity data and account/territory dimensions. OOB dashboard and PowerBI Sophia/research agent | I11: can we showcase Sophia here? (e.g. sales researcher, research agent) * copilot some foodbank food nfp specific pipeline management KPIs * Molly has some dashboards she can share with us | J11: Not started | L11: Should have | N11: L13
A12: Scenario 2 — delivered-price quote | B12: 0:20–0:45 | C12: Freight estimate request, pricing formula, margin, approval, versioning, and quote output. | D12: 2.1 | E12: From the opportunity, create a delivered-price quote using supplier cost of $1.36 per dozen. | F12: Quote: CPFB egg order draft | G12: CRM/CPQ / seller | H12: CE/D365 Sales: configure Quote and Quote Line forms for delivered price; carry opportunity context; add supplier cost per dozen and HATCH product fields. Create quote from opp need to add supplier cost to opp products and quote lines and order lines I guess | I12: how does selection work (for drop shipping) [for vendors] - A: every week procurement works with the vendors (farms) to understand the economics (supply price, quantities) - e.g. Penn needs 2 pallets, nearby farm has two > that’s the vendor - it's all manual right now | J12: Not started | K12: Drop ship related fields and option set values | L12: Must have | N12: L14
A13: Scenario 2 — delivered-price quote | B13: 0:20–0:45 | C13: Freight estimate request, pricing formula, margin, approval, versioning, and quote output. | D13: 2.2 | E13: Request or simulate a real-time freight estimate from the TMS for a consolidated two-stop refrigerated move totaling $1,550. | F13: Freight estimate request / response | G13: CRM + TMS / seller or logistics | H13: Power Platform + TMS ISV integration/mock: create freight-estimate request/response flow for consolidated two-stop refrigerated load; store freight estimate, source, confidence/status, and timestamp on the Quote. No F&O dependency in demo. Fake flow or JS API call that updates the quote (TBD on freight being its own line or an attribute of each quote line) | I13: walk through with Molly approvals - margin related, for the demo use emails - talk track: other channels of approvals eg teams | J13: Not started | L13: Must have | N13: L15
A14: Scenario 2 — delivered-price quote | B14: 0:20–0:45 | C14: Freight estimate request, pricing formula, margin, approval, versioning, and quote output. | D14: 2.3 | E14: Allocate freight across 16,200 dozen and add the $0.05 per dozen operating margin. | F14: Quote pricing calculation | G14: CRM/CPQ / seller | H14: CE/Power Platform: configure freight allocation calculation across 16,200 dozen; add operating margin per dozen. Use Dataverse formula column, plugin, or Power Automate calculation for demo. | I14: walk through with Molly what is 16,200? Is that 16 pallets of 200 dozens? 1 pallet: x dozens of eggs, 16,200 ~12 pallets freight is allocated across the products pricing | J14: Not started | L14: Must have | N14: L16
A15: Scenario 2 — delivered-price quote | B15: 0:20–0:45 | C15: Freight estimate request, pricing formula, margin, approval, versioning, and quote output. | D15: 2.4 | E15: Show calculated delivered price, total order value, margin dollars, and margin percentage. | F15: Quote economics / margin view | G15: CRM/CPQ + analytics / seller | H15: CE/Dataverse + Power BI: expose delivered price, total order value, margin dollars, and margin percentage on quote; optional KPI tile in quote/economics view. | I15: walk through with Molly | J15: Not started | L15: Must have | N15: L17
A16: Scenario 2 — delivered-price quote | B16: 0:20–0:45 | C16: Freight estimate request, pricing formula, margin, approval, versioning, and quote output. | D16: 2.5 | E16: Trigger an approval because the margin is below a configurable threshold, then approve using a manager role. | F16: Quote approval workflow | G16: CRM workflow / manager | H16: Power Automate + CE approvals: configure margin-threshold approval flow; manager approval task/action; approval status and audit trail on Quote. | J16: Not started | L16: Must have | N16: L18
A17: Scenario 2 — delivered-price quote | B17: 0:20–0:45 | C17: Freight estimate request, pricing formula, margin, approval, versioning, and quote output. | D17: 2.6 | E17: Generate a customer-ready quote and email or log the communication. | F17: Customer quote output / email activity | G17: CRM / seller | H17: CE + Power Automate/Word template: configure customer-ready quote output, email/log activity, and quote communication timeline. | J17: Not started | L17: Should have | N17: L19
A18: Scenario 2 — delivered-price quote | B18: 0:20–0:45 | C18: Freight estimate request, pricing formula, margin, approval, versioning, and quote output. | D18: 2.7 | E18: Revise the quote when the customer changes the split from 10/8 pallets to 12/6 pallets while preserving version history. | F18: Quote version history | G18: CRM/CPQ / seller | H18: CE Quote revisions: configure revised quote/version history; model customer split change from 10/8 to 12/6 pallets; retain prior version and approval context. | I18: what does 10/8 12/6 pallets mean, quote versions with different splits | J18: Not started | L18: Should have | N18: L20
A19: Scenario 3 — customer PO to commercial order | B19: 0:45–1:10 | C19: PO capture, validation, order creation, confirmation, two destinations, tasks, and order status. | D19: 3.1 | E19: Capture customer PO CPFB-0726-1842 and validate it against the accepted quote. | F19: PO: CPFB-0726-1842 | G19: CRM/OMS / seller or ops | H19: CE/Dataverse: configure PO Receipt table or commercial-order intake section; capture PO CPFB-0726-1842; relate PO to accepted quote; store source and validation status. | I19: how does a quote > order > to ultimately the PO for the customer Order > Invoice table OOB | J19: Not started | L19: Must have | N19: L21
A20: Scenario 3 — customer PO to commercial order | B20: 0:45–1:10 | C20: PO capture, validation, order creation, confirmation, two destinations, tasks, and order status. | D20: 3.2 | E20: Demonstrate duplicate PO detection, missing-field validation, and unusual quantity or price warnings. | F20: PO validation rules / exception flags | G20: CRM/OMS / operations | H20: CE/Power Platform: configure duplicate PO detection, required-field validations, unusual quantity/price warnings, and exception flag/status. | I20: unusual quantity - rules based | J20: Not started | L20: Must have | N20: L22
A21: Scenario 3 — customer PO to commercial order | B21: 0:45–1:10 | C21: PO capture, validation, order creation, confirmation, two destinations, tasks, and order status. | D21: 3.3 | E21: Create the commercial order without rekeying quote data. | F21: Commercial order generated from quote | G21: CRM/OMS / operations | H21: CE/Dataverse: configure Commercial Order table/process created from accepted quote + PO without rekeying; copy quote/customer/product/pricing fields; assign order status. Use OOB order and extend, and leverage the OOB movement from quote to product | J21: Not started | L21: Must have | N21: L23
A22: Scenario 3 — customer PO to commercial order | B22: 0:45–1:10 | C22: PO capture, validation, order creation, confirmation, two destinations, tasks, and order status. | D22: 3.4 | E22: Show two delivery destinations or split-order structure while preserving one customer-facing commercial relationship. | F22: Order destinations: Harrisburg and Chester County | G22: CRM/OMS / operations | H22: CE/Dataverse: configure Order Destination/Stop child table; support two destinations under one customer-facing Commercial Order; include pallets, delivery window, contacts, and handling instructions. Shipping slip custom table associated with the lines | I22: e.g. picking up from farm A, 20 pallets, 10 to foodbank A, 10 to food bank B, two purchases but one order | J22: Not started | L22: Must have | N22: L24
A23: Scenario 3 — customer PO to commercial order | B23: 0:45–1:10 | C23: PO capture, validation, order creation, confirmation, two destinations, tasks, and order status. | D23: 3.5 | E23: Generate customer order confirmation and internal tasks for supply confirmation, transportation release, and finance visibility. | F23: Order confirmation + task list | G23: CRM/OMS workflow / seller + ops | H23: Power Automate + CE: generate customer order confirmation and internal tasks for supply confirmation, transportation release, and finance visibility. | I23: transportation visibility - TMS statuses, etc. (order in transit, delayed, est delivery) finance visibility - reporting | J23: Not started | L23: Should have | N23: L25
A24: Scenario 3 — customer PO to commercial order | B24: 0:45–1:10 | C24: PO capture, validation, order creation, confirmation, two destinations, tasks, and order status. | D24: 3.6 | E24: Demonstrate order changes, cancellation, approval, and audit history. | F24: Order audit trail | G24: CRM/OMS / operations manager | H24: CE auditing + Power Platform: configure order change/cancel approval path; enable Dataverse audit history for price, quantity, PO, order status, and approval changes. | J24: Not started | L24: Should have | N24: L26
A25: Scenario 3 — customer PO to commercial order | B25: 0:45–1:10 | C25: PO capture, validation, order creation, confirmation, two destinations, tasks, and order status. | D25: 3.7 | E25: Show a cross-functional order dashboard with pending, active, exception, delivered, and invoice-ready statuses. | F25: Order dashboard | G25: CRM/OMS + analytics / cross-functional | H25: Power BI + CE views: build cross-functional order dashboard with pending, active, exception, delivered, and invoice-ready statuses; use Commercial Order, Order Destination, Shipment Event, and Exception records in Dataverse. | J25: Not started | L25: Should have | N25: L27
A26: Scenario 4 — execution and exception | B26: 1:10–1:30 | C26: TMS handoff, status, delay alert, customer communication, POD, shortage/rejection, and invoice-ready status. | D26: 4.1 | E26: Release the order to the TMS with origin, destinations, product, quantity, temperature, dates, references, and special instructions. | F26: TMS release payload / shipment request | G26: CRM/OMS + TMS / operations | H26: CE/Dataverse + Power Platform + TMS ISV integration: configure order release payload; map origin, destinations, product, quantity, temperature, dates, references, and special instructions; use API/mock integration to TMS. No Dual-Write/F&O in demo. Stub out as flow or JS to call TMS passing details from CRM | I26: Discussion with Molly/Serena - do we want to do a live integration mock up or just setup pre-populated records? A: do a stub mockup integration Temperature: for the broker, does the van need to stay at x*F (product requirement) | J26: Not started | L26: Must have | N26: L28
A27: Scenario 4 — execution and exception | B27: 1:10–1:30 | C27: TMS handoff, status, delay alert, customer communication, POD, shortage/rejection, and invoice-ready status. | D27: 4.2 | E27: Receive shipment ID, carrier, booked cost, pickup status, ETA, and tracking events back into the customer order. | F27: Shipment status on order | G27: TMS + CRM/OMS / logistics | H27: TMS ISV + Dataverse Shipment Event table: configure shipment ID, carrier, booked cost, pickup status, ETA, and tracking events returned to the customer order through event/API integration. | J27: Not started | L27: Must have | N27: L29
A28: Scenario 4 — execution and exception | B28: 1:10–1:30 | C28: TMS handoff, status, delay alert, customer communication, POD, shortage/rejection, and invoice-ready status. | D28: 4.3 | E28: Process a four-hour delay event and show alert routing, internal ownership, customer communication, and timeline history. | F28: Delay exception: revised ETA | G28: TMS + CRM workflow / logistics + seller | H28: Power Automate + CE/TMS eventing: configure delay exception event, alert routing, owner assignment, customer communication task/email, and timeline history. | I28: is this a delay event in the outbound transportation or is this a delay event (after 4 hours do something) - if the latter we can showcase sales sequence. A: basically status updates | J28: Not started | L28: Must have | N28: L30
A29: Scenario 4 — execution and exception | B29: 1:10–1:30 | C29: TMS handoff, status, delay alert, customer communication, POD, shortage/rejection, and invoice-ready status. | D29: 4.4 | E29: Receive POD and delivery details showing 17 pallets delivered and one pallet rejected for damage. | F29: POD / delivery variance record | G29: TMS + CRM/OMS / operations | H29: TMS/visibility ISV + CE/Dataverse: configure POD/delivery event record; store delivered/rejected pallet quantities and damage reason; link POD document to Commercial Order/Shipment Event. | I29: can we assume this is another integration event from TMS back to CRM? Who handles the quality check, rejection, disposal, etc. TMS or CRM? POD - Proof of Delivery (e.g. carrier upload PO to TMS, back to CRM, close to order and reflect actual status of the delivery) | J29: Not started | L29: Must have | N29: L31
A30: Scenario 4 — execution and exception | B30: 1:10–1:30 | C30: TMS handoff, status, delay alert, customer communication, POD, shortage/rejection, and invoice-ready status. | D30: 4.5 | E30: Launch a quantity-variance exception workflow and revise invoice-ready quantity while preserving original order and shipment data. | F30: Quantity variance workflow | G30: CRM/OMS workflow / operations + finance | H30: CE/Power Platform: configure quantity-variance exception workflow; revise invoice-ready quantity while preserving original order and shipment data in audit/history. | I30: walk through with Molly - e.g. is this a scenario 4.4 wher eonly 17 were sent and drop shipped hence 1 invoice for 17 is generated and a report shows open orders and remaining qtys who owns what here (TMS own the fact that 17 got delivered? 17 from TMS goes back to CRM? Who creates invoices A: If order was for 18, 17 delivered, then close the order, invoice just for 17. | J30: Not started | L30: Must have | N30: L32
A31: Scenario 4 — execution and exception | B31: 1:10–1:30 | C31: TMS handoff, status, delay alert, customer communication, POD, shortage/rejection, and invoice-ready status. | D31: 4.6 | E31: Link POD and exception documents to the order and demonstrate the invoice-ready handoff to QuickBooks. | F31: Invoice-ready handoff / document links | G31: CRM/OMS + finance integration / finance | H31: CE + Power Platform + QuickBooks handoff: configure invoice-ready flag/handoff after POD and variance review; link exception/POD documents; demo Phase 1 finance handoff without F&O. | I31: What is a POD - Proof of Delivery Again how much do we want to stub out or demo the integration to Quickbooks - A: mock up of CRM sending payload of the approved invoice (*e.g. 17 pallets) | J31: Not started | L31: Should have | N31: L33
A32: Scenario 4 — execution and exception | B32: 1:10–1:30 | C32: TMS handoff, status, delay alert, customer communication, POD, shortage/rejection, and invoice-ready status. | D32: 4.7 | E32: Show what the seller, operations user, and finance user each see. | F32: Role-based views | G32: CRM/OMS + TMS + QuickBooks/finance / all roles | H32: CE security roles + TMS/QuickBooks/Power BI views: configure role-based experiences for seller, operations, and finance; show only relevant rows, dashboards, and actions per role. | J32: Not started | L32: Should have | N32: L34
A33: Scenario 5 — marketing, reporting, and administration | B33: 1:30–1:40 | C33: Campaign source, account health, dashboards, workflow configuration, permissions, and audit history. | D33: 5.1 | E33: Show how a marketing campaign or lead source can be connected to the account, opportunity, and resulting order through integration with HubSpot or another marketing platform. | F33: Campaign / lead-source attribution | G33: Marketing integration + CRM / admin | H33: Customer Insights - Journeys or external/HubSpot mock + CE: configure campaign/lead-source attribution to account, opportunity, and resulting order; keep external option noted if CI-J is not in Release 1 scope. | I33: Confirm OK to demo CI-J - A: Demo CI-J - showcase E2E CI-J demo notes - keep it simple * Segments * Journeys * opt in opt out Keep the marketing workflows demo light THE VALUE ADD - marketing - sales connectivity, large volumes email handling | J33: Not started | L33: Could have | N33: L35
A34: Scenario 5 — marketing, reporting, and administration | B34: 1:30–1:40 | C34: Campaign source, account health, dashboards, workflow configuration, permissions, and audit history. | D34: 5.2 | E34: Show dashboards for pipeline, forecast, account health, quote conversion, open orders, order exceptions, margin, and user adoption. | F34: Executive / operating dashboards | G34: Analytics / leadership | H34: Power BI: build executive/operating dashboards for pipeline, forecast, account health, quote conversion, open orders, exceptions, margin, and user adoption over Dataverse + TMS events + QuickBooks handoff data. Sales Research | I34: A: standard OOB BI capabilities, incl. PowerBI embedded capabilities | J34: Not started | L34: Should have | N34: L36
A35: Scenario 5 — marketing, reporting, and administration | B35: 1:30–1:40 | C35: Campaign source, account health, dashboards, workflow configuration, permissions, and audit history. | D35: 5.3 | E35: Demonstrate configurable alert or workflow changes by a trained business administrator without custom code. | F35: Workflow configuration screen | G35: CRM/low-code admin / business admin | H35: Power Platform admin: configure example low-code workflow/alert threshold change by business admin; show environment solution component, flow, or Dataverse choice/threshold table. Flow changes ? BPF revisions/versions | I35: Basic form, workflow changes, managing products, variables | J35: Not started | L35: Should have | N35: L37
A36: Scenario 5 — marketing, reporting, and administration | B36: 1:30–1:40 | C36: Campaign source, account health, dashboards, workflow configuration, permissions, and audit history. | D36: 5.4 | E36: Show role-based permissions by territory and function, and audit history for changes to price, quantity, margin, PO, and order status. | F36: Security role / audit history | G36: CRM/OMS admin / admin | H36: CE/Dataverse security + audit: configure territory/function-based roles; enable audit history for price, quantity, margin, PO, and order status changes. | J36: Not started | L36: Must have | N36: L38
A37: Scenario 5 — marketing, reporting, and administration | B37: 1:30–1:40 | C37: Campaign source, account health, dashboards, workflow configuration, permissions, and audit history. | D37: 5.5 | E37: Demonstrate data export, API access, or Power BI connectivity. | F37: Export/API/Power BI connection | G37: CRM/OMS + analytics / admin | H37: Dataverse API/export + Power BI: configure sample export/API endpoint/view and Power BI connection; optionally show integration monitoring table/dashboard. | J37: Not started | L37: Should have | N37: L39
A38: Implementation and support | B38: 1:40–1:55 | C38: Plan, team, HATCH effort, data migration, training, support, and risks. | D38: 6.1 | E38: Walk through implementation plan, milestones, governance, risks, and dependencies. | F38: Implementation plan | G38: Implementation lead | H38: Implementation planning artifact: create phased Release 1 plan by CE, Power Platform, CI-J/external marketing, TMS integration, Power BI, data migration, QuickBooks handoff, and security workstreams. Include blueprint decision gate for optional F&O only if compelling Release 1 business case emerges. | J38: Not started | L38: High | N38: Agenda
A39: Implementation and support | B39: 1:40–1:55 | C39: Plan, team, HATCH effort, data migration, training, support, and risks. | D39: 6.2 | E39: Identify vendor implementation team roles and expected HATCH effort by workstream. | F39: Team / RACI view | G39: Implementation lead | H39: RACI/workstream tracker: define owners for CE configuration, Power Platform flows, CI-J/marketing integration, TMS integration, Power BI, data migration, security, demo data, and QuickBooks handoff. | J39: Not started | L39: High | N39: Agenda
A40: Implementation and support | B40: 1:40–1:55 | C40: Plan, team, HATCH effort, data migration, training, support, and risks. | D40: 6.3 | E40: Explain data migration approach for accounts, contacts, orders, notes, files, and finance handoff data. | F40: Migration plan | G40: Data lead | H40: Data migration prep: create source-to-target mapping for accounts, contacts, delivery locations, products, quotes/orders, shipment references, documents, and finance handoff fields. | J40: Not started | L40: High | N40: Agenda
A41: Implementation and support | B41: 1:40–1:55 | C41: Plan, team, HATCH effort, data migration, training, support, and risks. | D41: 6.4 | E41: Describe training approach for sellers, operations, finance, and administrators. | F41: Training plan | G41: Change lead | H41: Training/change plan: create role-based training outline for seller, operations, finance, and admin demo roles; map each training persona to tracker steps. | J41: Not started | L41: High | N41: Agenda
...

Sheet Agenda Summary
A1: Agenda Summary
A2: Scenario timing, segment evidence, and build target counts.
A4: Segment | B4: Timing | C4: Expected evidence | D4: Build steps
A5: Introduction and architecture | B5: 0:00–0:05 | C5: Proposed modules, user roles, implementation partner, and system role. | D5: 1
A6: Scenario 1 — account, territory, and opportunity | B6: 0:05–0:20 | C6: Customer 360, relationship history, funding, health, territory, tasks, and demand opportunity. | D6: 6
A7: Scenario 2 — delivered-price quote | B7: 0:20–0:45 | C7: Freight estimate request, pricing formula, margin, approval, versioning, and quote output. | D7: 7
A8: Scenario 3 — customer PO to commercial order | B8: 0:45–1:10 | C8: PO capture, validation, order creation, confirmation, two destinations, tasks, and order status. | D8: 7
A9: Scenario 4 — execution and exception | B9: 1:10–1:30 | C9: TMS handoff, status, delay alert, customer communication, POD, shortage/rejection, and invoice-ready status. | D9: 7
A10: Scenario 5 — marketing, reporting, and administration | B10: 1:30–1:40 | C10: Campaign source, account health, dashboards, workflow configuration, permissions, and audit history. | D10: 5
A11: Implementation and support | B11: 1:40–1:55 | C11: Plan, team, HATCH effort, data migration, training, support, and risks. | D11: 6
A12: Evaluator questions | B12: 1:55–2:00 | C12: Targeted follow-ups and unresolved requirements. | D12: 1

Sheet Hero Records
A1: Hero Records and Sample Data
A2: Core records and sample values to pre-build or mock for the demo environment.
A4: Record / object | B4: Sample value | C4: Usage | D4: Source
A5: Account | B5: Central Pennsylvania Food Bank | C5: Scenario 1 account/customer 360 | D5: Demo actors and sample data
A6: Primary contact | B6: Jordan Lee, Director of Procurement | C6: Contact and relationship history | D6: Demo actors and sample data
A7: Territory / owner | B7: Mid-Atlantic / Whitney Murphy | C7: Territory ownership / assignment | D7: Demo actors and sample data
A8: Funding context | B8: Pennsylvania PASS eligible; current-year funding expires June 30 | C8: Funding and capacity context | D8: Demo actors and sample data
A9: Product | B9: Large cage-free eggs | C9: Opportunity, quote, order, shipment | D9: Demo actors and sample data
A10: Requested quantity | B10: 18 pallets / 16,200 dozen | C10: Opportunity and quote quantity | D10: Demo actors and sample data
A11: Supplier cost | B11: $1.36 per dozen | C11: Quote pricing input | D11: Demo actors and sample data
A12: Operating margin target | B12: $0.05 per dozen | C12: Quote pricing input | D12: Demo actors and sample data
A13: Origin | B13: Lancaster, Pennsylvania | C13: TMS release origin | D13: Demo actors and sample data
A14: Destination 1 | B14: Harrisburg, Pennsylvania — 12 pallets | C14: Split delivery destination | D14: Demo actors and sample data
A15: Destination 2 | B15: Chester County, Pennsylvania — 6 pallets | C15: Split delivery destination | D15: Demo actors and sample data
... A22: Finance handoff | B22: Invoice-ready after POD and quantity variance review | C22: QuickBooks handoff evidence | D22: Demo actors and sample data

Sheet Build Status Summary
A1: Build Status Summary
A2: Simple rollup formulas for tracking readiness by status and scenario.
A4: Status | B4: Count
A5: Not started | B5: =COUNTIF('Demo Build Tracker'!H:H,A5) -> 0
A6: In build | B6: =COUNTIF('Demo Build Tracker'!H:H,A6) -> 0
A7: Ready for dry run | B7: =COUNTIF('Demo Build Tracker'!H:H,A7) -> 0
A8: Validated | B8: =COUNTIF('Demo Build Tracker'!H:H,A8) -> 0
A9: Gap/Risk | B9: =COUNTIF('Demo Build Tracker'!H:H,A9) -> 0
A10: Out of scope | B10: =COUNTIF('Demo Build Tracker'!H:H,A10) -> 0
A13: Scenario | B13: Total steps | C13: Validated
A14: Introduction and architecture | B14: =COUNTIF('Demo Build Tracker'!A:A,A14) -> 1 | C14: =COUNTIFS('Demo Build Tracker'!A:A,A14,'Demo Build Tracker'!H:H,"Validated") -> 0
A15: Scenario 1 — account, territory, and opportunity | B15: =COUNTIF('Demo Build Tracker'!A:A,A15) -> 6 | C15: =COUNTIFS('Demo Build Tracker'!A:A,A15,'Demo Build Tracker'!H:H,"Validated") -> 0
A16: Scenario 2 — delivered-price quote | B16: =COUNTIF('Demo Build Tracker'!A:A,A16) -> 7 | C16: =COUNTIFS('Demo Build Tracker'!A:A,A16,'Demo Build Tracker'!H:H,"Validated") -> 0
A17: Scenario 3 — customer PO to commercial order | B17: =COUNTIF('Demo Build Tracker'!A:A,A17) -> 7 | C17: =COUNTIFS('Demo Build Tracker'!A:A,A17,'Demo Build Tracker'!H:H,"Validated") -> 0
A18: Scenario 4 — execution and exception | B18: =COUNTIF('Demo Build Tracker'!A:A,A18) -> 7 | C18: =COUNTIFS('Demo Build Tracker'!A:A,A18,'Demo Build Tracker'!H:H,"Validated") -> 0
A19: Scenario 5 — marketing, reporting, and administration | B19: =COUNTIF('Demo Build Tracker'!A:A,A19) -> 5 | C19: =COUNTIFS('Demo Build Tracker'!A:A,A19,'Demo Build Tracker'!H:H,"Validated") -> 0
A20: Implementation and support | B20: =COUNTIF('Demo Build Tracker'!A:A,A20) -> 6 | C20: =COUNTIFS('Demo Build Tracker'!A:A,A20,'Demo Build Tracker'!H:H,"Validated") -> 0
A21: Evaluator questions | B21: =COUNTIF('Demo Build Tracker'!A:A,A21) -> 1 | C21: =COUNTIFS('Demo Build Tracker'!A:A,A21,'Demo Build Tracker'!H:H,"Validated") -> 0

Sheet Scoring Weights
A1: Scoring Weights
A2: Scoring categories included in the uploaded vendor demo script.
A4: Category | B4: Weight | C4: Evaluator scoring notes
A5: Scenario 1 | B5: 0.15
A6: Scenario 2 | B6: 0.2
A7: Scenario 3 | B7: 0.15
A8: Scenario 4 | B8: 0.2
A9: Scenario 5 | B9: 0.15
A10: Usability and workflow efficiency | B10: 0.15
A11: Overall fit | B11: 0.05

Sheet Source Notes
A1: Source Notes
A2: Workbook provenance and usage notes.
A4: Field | B4: Value
A5: Source document | B5: HATCH_CRM_OMS_120_Minute_Demo_Script_Vendor.docx
A6: Source URL | B6: https://twodegrees1.sharepoint.com/:w:/t/HatchforHunger/IQCUtUWwUM_9RK7pMlWrwJIQAUE9RsK2x2IIQ7P5RRKjf7w?email=holson.yap%40slalom.com&e=IYuFkh
A7: How to use | B7: Use Demo Build Tracker as the build backlog; assign owners, update status, and link hero records or screenshots.
A8: Status definitions | B8: Not started, In build, Ready for dry run, Validated, Gap/Risk, Out of scope.
A9: Workbook note | B9: Use case wording is normalized into build-tracker language while preserving the uploaded script steps.
A10: Added column | B10: Demo build column added from an opinionated CE / CI-J / F&O / Power Platform build lens based on the Option 1 D365 solution hypothesis.
A11: CE-only update | B11: Demo build guidance updated to remove active F&O/Dual-Write scope from Release 1 demo. Blueprint phase should determine whether a compelling business reason exists to inject F&O in Release 1; otherwise demo POV remains CE + Power Platform + CI-J/external marketing + TMS ISV + QuickBooks + Power BI.

Sheet Demo Build Lens
A1: Demo Build Lens — CE-Only Release 1 POV
A2: Demo scope: D365 Sales/Dataverse + Power Platform + CI-J or external marketing + TMS ISV + QuickBooks + Power BI. F&O is not included in demo; evaluate during blueprint only if a compelling Release 1 business case exists.
A4: Layer | B4: Likely demo build | C4: Example tracker rows | D4: Build stance | E4: Risk / decision | F4: Source basis
A5: D365 CE / Sales / Dataverse | B5: Accounts, contacts, territories, opportunities, quotes, customer PO, commercial order, order destinations, shipment/event shadow records, exception records, audit, and security. | C5: 1.1-1.6, 2.1, 2.4, 2.7, 3.1-3.7, 4.2, 4.4-4.7, 5.4 | D5: Configure + custom Dataverse tables | E5: Keep the customer-facing commercial order in Dataverse; avoid introducing F&O as a duplicate order master in the demo. | F5: RFI and demo script center CRM/OMS on customer, quote, PO, commercial order, status, and exceptions.
A6: Power Platform | B6: Approvals, PO validation, duplicate detection, task generation, freight estimate mock/API flow, shipment event routing, exception workflow, invoice-ready flag, admin workflow change. | C6: 2.2, 2.3, 2.5, 3.2, 3.5, 4.1-4.6, 5.3 | D6: Low-code orchestration + integration | E6: Make workflows visible and easy to explain; avoid hiding core proof points in F&O or custom backend logic. | F6: Demo script requires freight estimate, pricing formula, margin approval, order workflows, alerts, and invoice-ready handoff.
A7: Customer Insights - Journeys / external marketing | B7: Campaign/lead-source attribution linked to account, opportunity, and resulting order; may be mocked if HubSpot or another tool remains external. | C7: 5.1 | D7: Optional configuration / mock | E7: Marketing ownership is open; keep this lightweight unless it is a key evaluation concern. | F7: RFI references marketing integration and attribution; demo script includes campaign/lead source scenario.
A8: TMS ISV / visibility integration | B8: Freight estimates, shipment creation, carrier status, ETA, delay events, POD, delivery variance, and transportation cost events returned to Dataverse. | C8: 2.2, 4.1-4.6 | D8: ISV/API mock for demo | E8: TMS is the execution system; CE shows status and exceptions but does not become the TMS. | F8: RFI and requirements identify TMS as transportation execution layer and integration source for freight estimates/events.
A9: QuickBooks / finance handoff | B9: Invoice-ready handoff after POD and variance review; QuickBooks remains Phase 1 accounting platform. | C9: 4.6, implementation rows | D9: Integration handoff / mock | E9: Do not demonstrate F&O finance unless blueprint creates a Release 1 business case. | F9: RFI describes QuickBooks Phase 1 and future ERP readiness later.
A10: Power BI | B10: Pipeline, forecast, account health, quote conversion, open orders, exceptions, margin, adoption, and invoice-ready reporting. | C10: 1.6, 3.7, 5.2 | D10: Dashboards from Dataverse + TMS events + QuickBooks handoff data | E10: Dashboards should validate the operating model, not become a separate build project. | F10: RFI and demo script require reporting across pipeline, orders, exceptions, and adoption.
A11: F&O decision gate | B11: Not in demo. During blueprint, test whether Release 1 needs F&O for customer/product master, AR subledger, sales order shadowing, or future ERP acceleration. | C11: 0.1, 6.1, 6.6, 7.1 | D11: Blueprint decision only | E11: Only inject F&O in Release 1 if the business case outweighs implementation weight and duplicate-order complexity. | F11: User POV and CE-first architecture indicate Release 1 demo should stay CE/Power Platform/CI-J/TMS/QuickBooks unless blueprint proves otherwise.
